Workbook

Sheet Costuri
C2: Costuri Grup Autoworld 2025
C3: Societate | D3: Cost training | E3: Cost diurna | F3: Cost cazare | G3: Cost transport | H3: Total cost RON | I3: Total cost EUR
C4: Autoworld | D4: =E27 -> 144512 | E4: =F27 -> 6429.5 | F4: =G27 -> 5546.75 | G4: =H27 -> 10575 | H4: =I27 -> 167063.25 | I4: =H4/5 -> 33412.65
C5: Autoworld International | D5: =E33 -> 63590 | E5: =F33 -> 8576.84 | F5: =G33 -> 10867 | G5: =H33 -> 10049 | H5: =I33 -> 93082.84 | I5: =H5/5 -> 18616.568
C6: Autoworld Premium | D6: =E39 -> 19901 | E6: =F39 -> 5786.5 | F6: =G39 -> 6308 | G6: =H39 -> 3060 | H6: =I39 -> 35055.5 | I6: =H6/5 -> 7011.1
C7: Autoworld Prestige | D7: =E46 -> 7782 | E7: =F46 -> 3105 | F7: =G46 -> 8308 | G7: =H46 -> 0 | H7: =I46 -> 19195 | I7: =H7/5 -> 3839
C8: Autoworld Plus | D8: =E55 -> 17481 | E8: =F55 -> 3088.5 | F8: =G55 -> 4897 | G8: =H55 -> 4147 | H8: =I55 -> 29613.5 | I8: =H8/5 -> 5922.7
C9: Autoworld Next | D9: =E61 -> 6698 | E9: =F61 -> 172.5 | F9: =G61 -> 0 | G9: =H61 -> 716 | H9: =I61 -> 7586.5 | I9: =H9/5 -> 1517.3
C10: Autoworld One | D10: =E67 -> 0 | E10: =F67 -> 1495 | F10: =G67 -> 1850 | G10: =H67 -> 300 | H10: =I67 -> 3645 | I10: =H10/5 -> 729
C11: Autoworld Insurance | D11: =E71 -> 0 | E11: =F71 -> 115 | F11: =G71 -> 0 | G11: =H71 -> 0 | H11: =I71 -> 115 | I11: =H11/5 -> 23
C12: Total | D12: =SUM(D4:D11) -> 259964 | E12: =SUM(E4:E11) -> 28768.84 | F12: =SUM(F4:F11) -> 37776.75 | G12: =SUM(G4:G11) -> 28847 | H12: =SUM(H4:H11) -> 355356.59 | I12: =SUM(I4:I11) -> 71071.318
B15: Autoworld | C15: Departament | D15: Nr zile | E15: Cost training | F15: Cost diurna | G15: Cost cazare | H15: Cost transport | I15: Total cost cursuri/conferinte
C16: Conducere | D16: =SUMIFS('Cursuri AW'!$H:$H,'Cursuri AW'!$B:$B,Costuri!C16) -> 50 | E16: =SUMIFS('Cursuri AW'!$N:$N,'Cursuri AW'!$B:$B,Costuri!C16) -> 118301 | F16: =SUMIFS('Cursuri AW'!$O:$O,'Cursuri AW'!$B:$B,Costuri!C16) -> 3974.5 | G16: =SUMIFS('Cursuri AW'!$P:$P,'Cursuri AW'!$B:$B,Costuri!C16) -> 2310 | H16: =SUMIFS('Cursuri AW'!$Q:$Q,'Cursuri AW'!$B:$B,Costuri!C16)+SUMIFS('Cursuri AW'!$R:$R,'Cursuri AW'!$B:$B,Costuri!C16) -> 9378 | I16: =SUMIFS('Cursuri AW'!$S:$S,'Cursuri AW'!$B:$B,Costuri!C16) -> 133963.5
C17: Marketing | D17: =SUMIFS('Cursuri AW'!$H:$H,'Cursuri AW'!$B:$B,Costuri!C17) -> 5 | E17: =SUMIFS('Cursuri AW'!$N:$N,'Cursuri AW'!$B:$B,Costuri!C17) -> 3017 | F17: =SUMIFS('Cursuri AW'!$O:$O,'Cursuri AW'!$B:$B,Costuri!C17) -> 230 | G17: =SUMIFS('Cursuri AW'!$P:$P,'Cursuri AW'!$B:$B,Costuri!C17) -> 0 | H17: =SUMIFS('Cursuri AW'!$Q:$Q,'Cursuri AW'!$B:$B,Costuri!C17)+SUMIFS('Cursuri AW'!$R:$R,'Cursuri AW'!$B:$B,Costuri!C17) -> 0 | I17: =SUMIFS('Cursuri AW'!$S:$S,'Cursuri AW'!$B:$B,Costuri!C17) -> 3247
C18: Vanzari VW | D18: =SUMIFS('Cursuri AW'!$H:$H,'Cursuri AW'!$B:$B,Costuri!C18) -> 11 | E18: =SUMIFS('Cursuri AW'!$N:$N,'Cursuri AW'!$B:$B,Costuri!C18) -> 3545 | F18: =SUMIFS('Cursuri AW'!$O:$O,'Cursuri AW'!$B:$B,Costuri!C18) -> 595 | G18: =SUMIFS('Cursuri AW'!$P:$P,'Cursuri AW'!$B:$B,Costuri!C18) -> 470 | H18: =SUMIFS('Cursuri AW'!$Q:$Q,'Cursuri AW'!$B:$B,Costuri!C18)+SUMIFS('Cursuri AW'!$R:$R,'Cursuri AW'!$B:$B,Costuri!C18) -> 1020 | I18: =SUMIFS('Cursuri AW'!$S:$S,'Cursuri AW'!$B:$B,Costuri!C18) -> 5630
C19: Service VW | D19: =SUMIFS('Cursuri AW'!$H:$H,'Cursuri AW'!$B:$B,Costuri!C19) -> 4 | E19: =SUMIFS('Cursuri AW'!$N:$N,'Cursuri AW'!$B:$B,Costuri!C19) -> 2011 | F19: =SUMIFS('Cursuri AW'!$O:$O,'Cursuri AW'!$B:$B,Costuri!C19) -> 230 | G19: =SUMIFS('Cursuri AW'!$P:$P,'Cursuri AW'!$B:$B,Costuri!C19) -> 553.75 | H19: =SUMIFS('Cursuri AW'!$Q:$Q,'Cursuri AW'!$B:$B,Costuri!C19)+SUMIFS('Cursuri AW'!$R:$R,'Cursuri AW'!$B:$B,Costuri!C19) -> 0 | I19: =SUMIFS('Cursuri AW'!$S:$S,'Cursuri AW'!$B:$B,Costuri!C19) -> 2794.75
C20: Vanzari Audi | D20: =SUMIFS('Cursuri AW'!$H:$H,'Cursuri AW'!$B:$B,Costuri!C20) -> 5 | E20: =SUMIFS('Cursuri AW'!$N:$N,'Cursuri AW'!$B:$B,Costuri!C20) -> 3545 | F20: =SUMIFS('Cursuri AW'!$O:$O,'Cursuri AW'!$B:$B,Costuri!C20) -> 240 | G20: =SUMIFS('Cursuri AW'!$P:$P,'Cursuri AW'!$B:$B,Costuri!C20) -> 0 | H20: =SUMIFS('Cursuri AW'!$Q:$Q,'Cursuri AW'!$B:$B,Costuri!C20)+SUMIFS('Cursuri AW'!$R:$R,'Cursuri AW'!$B:$B,Costuri!C20) -> 0 | I20: =SUMIFS('Cursuri AW'!$S:$S,'Cursuri AW'!$B:$B,Costuri!C20) -> 3785
C21: Piese de schimb si accesorii Audi | D21: =SUMIFS('Cursuri AW'!$H:$H,'Cursuri AW'!$B:$B,Costuri!C21) -> 3 | E21: =SUMIFS('Cursuri AW'!$N:$N,'Cursuri AW'!$B:$B,Costuri!C21) -> 1508 | F21: =SUMIFS('Cursuri AW'!$O:$O,'Cursuri AW'!$B:$B,Costuri!C21) -> 172.5 | G21: =SUMIFS('Cursuri AW'!$P:$P,'Cursuri AW'!$B:$B,Costuri!C21) -> 1176 | H21: =SUMIFS('Cursuri AW'!$Q:$Q,'Cursuri AW'!$B:$B,Costuri!C21)+SUMIFS('Cursuri AW'!$R:$R,'Cursuri AW'!$B:$B,Costuri!C21) -> 0 | I21: =SUMIFS('Cursuri AW'!$S:$S,'Cursuri AW'!$B:$B,Costuri!C21) -> 2856.5
C22: Vanzari Volvo | D22: =SUMIFS('Cursuri AW'!$H:$H,'Cursuri AW'!$B:$B,Costuri!C22) -> 1 | E22: =SUMIFS('Cursuri AW'!$N:$N,'Cursuri AW'!$B:$B,Costuri!C22) -> 3545 | F22: =SUMIFS('Cursuri AW'!$O:$O,'Cursuri AW'!$B:$B,Costuri!C22) -> 0 | G22: =SUMIFS('Cursuri AW'!$P:$P,'Cursuri AW'!$B:$B,Costuri!C22) -> 0 | H22: =SUMIFS('Cursuri AW'!$Q:$Q,'Cursuri AW'!$B:$B,Costuri!C22)+SUMIFS('Cursuri AW'!$R:$R,'Cursuri AW'!$B:$B,Costuri!C22) -> 0 | I22: =SUMIFS('Cursuri AW'!$S:$S,'Cursuri AW'!$B:$B,Costuri!C22) -> 3545
C23: Vanzari DWA | D23: =SUMIFS('Cursuri AW'!$H:$H,'Cursuri AW'!$B:$B,Costuri!C23) -> 1 | E23: =SUMIFS('Cursuri AW'!$N:$N,'Cursuri AW'!$B:$B,Costuri!C23) -> 3545 | F23: =SUMIFS('Cursuri AW'!$O:$O,'Cursuri AW'!$B:$B,Costuri!C23) -> 0 | G23: =SUMIFS('Cursuri AW'!$P:$P,'Cursuri AW'!$B:$B,Costuri!C23) -> 0 | H23: =SUMIFS('Cursuri AW'!$Q:$Q,'Cursuri AW'!$B:$B,Costuri!C23)+SUMIFS('Cursuri AW'!$R:$R,'Cursuri AW'!$B:$B,Costuri!C23) -> 0 | I23: =SUMIFS('Cursuri AW'!$S:$S,'Cursuri AW'!$B:$B,Costuri!C23) -> 3545
C24: Vanzari MG | D24: =SUMIFS('Cursuri AW'!$H:$H,'Cursuri AW'!$B:$B,Costuri!C24) -> 1 | E24: =SUMIFS('Cursuri AW'!$N:$N,'Cursuri AW'!$B:$B,Costuri!C24) -> 3545 | F24: =SUMIFS('Cursuri AW'!$O:$O,'Cursuri AW'!$B:$B,Costuri!C24) -> 0 | G24: =SUMIFS('Cursuri AW'!$P:$P,'Cursuri AW'!$B:$B,Costuri!C24) -> 0 | H24: =SUMIFS('Cursuri AW'!$Q:$Q,'Cursuri AW'!$B:$B,Costuri!C24)+SUMIFS('Cursuri AW'!$R:$R,'Cursuri AW'!$B:$B,Costuri!C24) -> 0 | I24: =SUMIFS('Cursuri AW'!$S:$S,'Cursuri AW'!$B:$B,Costuri!C24) -> 3545
C25: Service MG | D25: =SUMIFS('Cursuri AW'!$H:$H,'Cursuri AW'!$B:$B,Costuri!C25) -> 9 | E25: =SUMIFS('Cursuri AW'!$N:$N,'Cursuri AW'!$B:$B,Costuri!C25) -> 1950 | F25: =SUMIFS('Cursuri AW'!$O:$O,'Cursuri AW'!$B:$B,Costuri!C25) -> 987.5 | G25: =SUMIFS('Cursuri AW'!$P:$P,'Cursuri AW'!$B:$B,Costuri!C25) -> 1037 | H25: =SUMIFS('Cursuri AW'!$Q:$Q,'Cursuri AW'!$B:$B,Costuri!C25)+SUMIFS('Cursuri AW'!$R:$R,'Cursuri AW'!$B:$B,Costuri!C25) -> 177 | I25: =SUMIFS('Cursuri AW'!$S:$S,'Cursuri AW'!$B:$B,Costuri!C25) -> 4151.5
C26: Daune | D26: =SUMIFS('Cursuri AW'!$H:$H,'Cursuri AW'!$B:$B,Costuri!C26) -> 0 | E26: =SUMIFS('Cursuri AW'!$N:$N,'Cursuri AW'!$B:$B,Costuri!C26) -> 0 | F26: =SUMIFS('Cursuri AW'!$O:$O,'Cursuri AW'!$B:$B,Costuri!C26) -> 0 | G26: =SUMIFS('Cursuri AW'!$P:$P,'Cursuri AW'!$B:$B,Costuri!C26) -> 0 | H26: =SUMIFS('Cursuri AW'!$Q:$Q,'Cursuri AW'!$B:$B,Costuri!C26)+SUMIFS('Cursuri AW'!$R:$R,'Cursuri AW'!$B:$B,Costuri!C26) -> 0 | I26: =SUMIFS('Cursuri AW'!$S:$S,'Cursuri AW'!$B:$B,Costuri!C26) -> 0
C27: Total | D27: =SUM(D16:D26) -> 90 | E27: =SUM(E16:E26) -> 144512 | F27: =SUM(F16:F26) -> 6429.5 | G27: =SUM(G16:G26) -> 5546.75 | H27: =SUM(H16:H26) -> 10575 | I27: =SUM(I16:I26) -> 167063.25
B29: Autoworld International | C29: Departament | D29: Nr zile | E29: Cost training | F29: Cost diurna | G29: Cost cazare | H29: Cost transport | I29: Total cost cursuri/conferinte
C30: Vanzari VW | D30: =SUMIFS('Cursuri AW International'!$H:$H,'Cursuri AW International'!$B:$B,Costuri!C30) -> 66 | E30: =SUMIFS('Cursuri AW International'!$N:$N,'Cursuri AW International'!$B:$B,Costuri!C30) -> 44786 | F30: =SUMIFS('Cursuri AW International'!$O:$O,'Cursuri AW International'!$B:$B,Costuri!C30) -> 4664.34 | G30: =SUMIFS('Cursuri AW International'!$P:$P,'Cursuri AW International'!$B:$B,Costuri!C30) -> 2361 | H30: =SUMIFS('Cursuri AW International'!$Q:$Q,'Cursuri AW International'!$B:$B,Costuri!C30)+SUMIFS('Cursuri AW International'!$R:$R,'Cursuri AW International'!$B:$B,Costuri!C30) -> 5528 | I30: =SUMIFS('Cursuri AW International'!$S:$S,'Cursuri AW International'!$B:$B,Costuri!C30) -> 57339.34
C31: Service VW | D31: =SUMIFS('Cursuri AW International'!$H:$H,'Cursuri AW International'!$B:$B,Costuri!C31) -> 67 | E31: =SUMIFS('Cursuri AW International'!$N:$N,'Cursuri AW International'!$B:$B,Costuri!C31) -> 18804 | F31: =SUMIFS('Cursuri AW International'!$O:$O,'Cursuri AW International'!$B:$B,Costuri!C31) -> 3797.5 | G31: =SUMIFS('Cursuri AW International'!$P:$P,'Cursuri AW International'!$B:$B,Costuri!C31) -> 8506 | H31: =SUMIFS('Cursuri AW International'!$Q:$Q,'Cursuri AW International'!$B:$B,Costuri!C31)+SUMIFS('Cursuri AW International'!$R:$R,'Cursuri AW International'!$B:$B,Costuri!C31) -> 4521 | I31: =SUMIFS('Cursuri AW International'!$S:$S,'Cursuri AW International'!$B:$B,Costuri!C31) -> 35628.5
C32: Piese de schimb si accesorii VW | D32: =SUMIFS('Cursuri AW International'!$H:$H,'Cursuri AW International'!$B:$B,Costuri!C32) -> 2 | E32: =SUMIFS('Cursuri AW International'!$N:$N,'Cursuri AW International'!$B:$B,Costuri!C32) -> 0 | F32: =SUMIFS('Cursuri AW International'!$O:$O,'Cursuri AW International'!$B:$B,Costuri!C32) -> 115 | G32: =SUMIFS('Cursuri AW International'!$P:$P,'Cursuri AW International'!$B:$B,Costuri!C32) -> 0 | H32: =SUMIFS('Cursuri AW International'!$Q:$Q,'Cursuri AW International'!$B:$B,Costuri!C32)+SUMIFS('Cursuri AW International'!$R:$R,'Cursuri AW International'!$B:$B,Costuri!C32) -> 0 | I32: =SUMIFS('Cursuri AW International'!$S:$S,'Cursuri AW International'!$B:$B,Costuri!C32) -> 115
C33: Total | D33: =SUM(D30:D32) -> 135 | E33: =SUM(E30:E32) -> 63590 | F33: =SUM(F30:F32) -> 8576.84 | G33: =SUM(G30:G32) -> 10867 | H33: =SUM(H30:H32) -> 10049 | I33: =SUM(I30:I32) -> 93082.84
B35: Autoworld Premium | C35: Departament | D35: Nr zile | E35: Cost training | F35: Cost diurna | G35: Cost cazare | H35: Cost transport | I35: Total cost cursuri/conferinte
C36: Vanzari Audi | D36: =SUMIFS('Cursuri AW Premium'!$H:$H,'Cursuri AW Premium'!$B:$B,Costuri!C36) -> 24 | E36: =SUMIFS('Cursuri AW Premium'!$N:$N,'Cursuri AW Premium'!$B:$B,Costuri!C36) -> 6698 | F36: =SUMIFS('Cursuri AW Premium'!$O:$O,'Cursuri AW Premium'!$B:$B,Costuri!C36) -> 2617.5 | G36: =SUMIFS('Cursuri AW Premium'!$P:$P,'Cursuri AW Premium'!$B:$B,Costuri!C36) -> 0 | H36: =SUMIFS('Cursuri AW Premium'!$Q:$Q,'Cursuri AW Premium'!$B:$B,Costuri!C36)+SUMIFS('Cursuri AW Premium'!$R:$R,'Cursuri AW Premium'!$B:$B,Costuri!C36) -> 510 | I36: =SUMIFS('Cursuri AW Premium'!$S:$S,'Cursuri AW Premium'!$B:$B,Costuri!C36) -> 9825.5
C37: Service Audi | D37: =SUMIFS('Cursuri AW Premium'!$H:$H,'Cursuri AW Premium'!$B:$B,Costuri!C37) -> 38 | E37: =SUMIFS('Cursuri AW Premium'!$N:$N,'Cursuri AW Premium'!$B:$B,Costuri!C37) -> 13203 | F37: =SUMIFS('Cursuri AW Premium'!$O:$O,'Cursuri AW Premium'!$B:$B,Costuri!C37) -> 2611 | G37: =SUMIFS('Cursuri AW Premium'!$P:$P,'Cursuri AW Premium'!$B:$B,Costuri!C37) -> 6308 | H37: =SUMIFS('Cursuri AW Premium'!$Q:$Q,'Cursuri AW Premium'!$B:$B,Costuri!C37)+SUMIFS('Cursuri AW Premium'!$R:$R,'Cursuri AW Premium'!$B:$B,Costuri!C37) -> 2550 | I37: =SUMIFS('Cursuri AW Premium'!$S:$S,'Cursuri AW Premium'!$B:$B,Costuri!C37) -> 24672
C38: Piese de schimb si accesorii Audi | D38: =SUMIFS('Cursuri AW Premium'!$H:$H,'Cursuri AW Premium'!$B:$B,Costuri!C38) -> 5 | E38: =SUMIFS('Cursuri AW Premium'!$N:$N,'Cursuri AW Premium'!$B:$B,Costuri!C38) -> 0 | F38: =SUMIFS('Cursuri AW Premium'!$O:$O,'Cursuri AW Premium'!$B:$B,Costuri!C38) -> 558 | G38: =SUMIFS('Cursuri AW Premium'!$P:$P,'Cursuri AW Premium'!$B:$B,Costuri!C38) -> 0 | H38: =SUMIFS('Cursuri AW Premium'!$Q:$Q,'Cursuri AW Premium'!$B:$B,Costuri!C38)+SUMIFS('Cursuri AW Premium'!$R:$R,'Cursuri AW Premium'!$B:$B,Costuri!C38) -> 0 | I38: =SUMIFS('Cursuri AW Premium'!$S:$S,'Cursuri AW Premium'!$B:$B,Costuri!C38) -> 558
C39: Total | D39: =SUM(D36:D38) -> 67 | E39: =SUM(E36:E38) -> 19901 | F39: =SUM(F36:F38) -> 5786.5 | G39: =SUM(G36:G38) -> 6308 | H39: =SUM(H36:H38) -> 3060 | I39: =SUM(I36:I38) -> 35055.5
B41: Autoworld Prestige | C41: Departament | D41: Nr zile | E41: Cost training | F41: Cost diurna | G41: Cost cazare | H41: Cost transport | I41: Total cost cursuri/conferinte
C42: Vanzari Volvo | D42: =SUMIFS('Cursuri AW Prestige'!$H:$H,'Cursuri AW Prestige'!$B:$B,Costuri!C42) -> 10 | E42: =SUMIFS('Cursuri AW Prestige'!$N:$N,'Cursuri AW Prestige'!$B:$B,Costuri!C42) -> 3152 | F42: =SUMIFS('Cursuri AW Prestige'!$O:$O,'Cursuri AW Prestige'!$B:$B,Costuri!C42) -> 517.5 | G42: =SUMIFS('Cursuri AW Prestige'!$P:$P,'Cursuri AW Prestige'!$B:$B,Costuri!C42) -> 2867 | H42: =SUMIFS('Cursuri AW Prestige'!$Q:$Q,'Cursuri AW Prestige'!$B:$B,Costuri!C42)+SUMIFS('Cursuri AW Prestige'!$R:$R,'Cursuri AW Prestige'!$B:$B,Costuri!C42) -> 0 | I42: =SUMIFS('Cursuri AW Prestige'!$S:$S,'Cursuri AW Prestige'!$B:$B,Costuri!C42) -> 6536.5
C43: Vanzari DWA | D43: =SUMIFS('Cursuri AW Prestige'!$H:$H,'Cursuri AW Prestige'!$B:$B,Costuri!C43) -> 0 | E43: =SUMIFS('Cursuri AW Prestige'!$N:$N,'Cursuri AW Prestige'!$B:$B,Costuri!C43) -> 0 | F43: =SUMIFS('Cursuri AW Prestige'!$O:$O,'Cursuri AW Prestige'!$B:$B,Costuri!C43) -> 0 | G43: =SUMIFS('Cursuri AW Prestige'!$P:$P,'Cursuri AW Prestige'!$B:$B,Costuri!C43) -> 0 | H43: =SUMIFS('Cursuri AW Prestige'!$Q:$Q,'Cursuri AW Prestige'!$B:$B,Costuri!C43)+SUMIFS('Cursuri AW Prestige'!$R:$R,'Cursuri AW Prestige'!$B:$B,Costuri!C43) -> 0 | I43: =SUMIFS('Cursuri AW Prestige'!$S:$S,'Cursuri AW Prestige'!$B:$B,Costuri!C43) -> 0
C44: Service Volvo | D44: =SUMIFS('Cursuri AW Prestige'!$H:$H,'Cursuri AW Prestige'!$B:$B,Costuri!C44) -> 48 | E44: =SUMIFS('Cursuri AW Prestige'!$N:$N,'Cursuri AW Prestige'!$B:$B,Costuri!C44) -> 4630 | F44: =SUMIFS('Cursuri AW Prestige'!$O:$O,'Cursuri AW Prestige'!$B:$B,Costuri!C44) -> 2587.5 | G44: =SUMIFS('Cursuri AW Prestige'!$P:$P,'Cursuri AW Prestige'!$B:$B,Costuri!C44) -> 5441 | H44: =SUMIFS('Cursuri AW Prestige'!$Q:$Q,'Cursuri AW Prestige'!$B:$B,Costuri!C44)+SUMIFS('Cursuri AW Prestige'!$R:$R,'Cursuri AW Prestige'!$B:$B,Costuri!C44) -> 0 | I44: =SUMIFS('Cursuri AW Prestige'!$S:$S,'Cursuri AW Prestige'!$B:$B,Costuri!C44) -> 12658.5
C45: Piese de schimb si accesorii Volvo | D45: =SUMIFS('Cursuri AW Prestige'!$H:$H,'Cursuri AW Prestige'!$B:$B,Costuri!C45) -> 0 | E45: =SUMIFS('Cursuri AW Prestige'!$N:$N,'Cursuri AW Prestige'!$B:$B,Costuri!C45) -> 0 | F45: =SUMIFS('Cursuri AW Prestige'!$O:$O,'Cursuri AW Prestige'!$B:$B,Costuri!C45) -> 0 | G45: =SUMIFS('Cursuri AW Prestige'!$P:$P,'Cursuri AW Prestige'!$B:$B,Costuri!C45) -> 0 | H45: =SUMIFS('Cursuri AW Prestige'!$Q:$Q,'Cursuri AW Prestige'!$B:$B,Costuri!C45)+SUMIFS('Cursuri AW Prestige'!$R:$R,'Cursuri AW Prestige'!$B:$B,Costuri!C45) -> 0 | I45: =SUMIFS('Cursuri AW Prestige'!$S:$S,'Cursuri AW Prestige'!$B:$B,Costuri!C45) -> 0
C46: Total | D46: =SUM(D42:D45) -> 58 | E46: =SUM(E42:E45) -> 7782 | F46: =SUM(F42:F45) -> 3105 | G46: =SUM(G42:G45) -> 8308 | H46: =SUM(H42:H45) -> 0 | I46: =SUM(I42:I45) -> 19195
...

Sheet Cursuri AW
A1: Nume & Prenume | B1: Departament | C1: Denumire Curs / Conferinta | D1: Cod curs | E1: Durata curs | F1: Data inceput curs | G1: Data final curs | H1: Nr zile curs | I1: Locatia | J1: Deplasare | K1: Nec. Nr. | L1: OD | M1: Act adit. | N1: Taxa training | O1: Diurna | P1: Cazare | Q1: Transport | R1: Taxi | S1: COST TOTAL
A2: Mezei Laszlo Lehel | B2: Conducere | C2: Conferinta Mazda | E2: 45674 | F2: 45674 | G2: 45674 | H2: 1 | I2: Bucuresti | J2: Avion | L2: 77 | O2: 57.5 | R2: 100 | S2: =SUM(N2:R2) -> 157.5
A3: Szabo Alexandru | B3: Conducere | C3: Conferinta Mazda | E3: 45674 | F3: 45674 | G3: 45674 | H3: 1 | I3: Bucuresti | J3: Avion | L3: 78 | O3: 57.5 | R3: 100 | S3: =SUM(N3:R3) -> 157.5
A4: Enache Sebastian | B4: Conducere | C4: Conferinta Mazda | E4: 45674 | F4: 45674 | G4: 45674 | H4: 1 | I4: Bucuresti | J4: Avion | L4: 79 | O4: 57.5 | R4: 100 | S4: =SUM(N4:R4) -> 157.5
A5: Ungurean Ileana | B5: Vanzari VW | C5: Intalniri business | E5: 15-16.01.2025 | F5: 45672 | G5: 45673 | H5: 2 | I5: Bucuresti | J5: Avion | L5: 96 | O5: 115 | P5: 470 | Q5: 870 | R5: 150 | S5: =SUM(N5:R5) -> 1605
A6: Toma Cezar | B6: Service VW | C6: PDA 1M1 P.1 Coordonator Siguranta Produselor | D6: PDA 1M1 P.1 | E6: 21-23.01.2025 | F6: 45677 | G6: 45680 | H6: 3 | I6: Bucuresti | J6: Masina | L6: 171 | N6: 1508 | O6: 172.5 | P6: 216.75 | S6: =SUM(N6:R6) -> 1897.25
A7: Cirlea Dan | B7: Service VW | C7: Examen tehnician service Skoda | E7: 45680 | F7: 45679 | G7: 45680 | H7: 1 | I7: Bucuresti | J7: Masina | L7: 173 | N7: 503 | O7: 57.5 | P7: 337 | S7: =SUM(N7:R7) -> 897.5
A8: Dan Vasile | B8: Service MG | C8: Curs Mazda | E8: 29-31.01.2025 | F8: 45685 | G8: 45689 | H8: 4 | I8: Klagenfurt Austria | J8: Masina | N8: 1950 | O8: 700 | Q8: 177 | S8: =SUM(N8:R8) -> 2827
A9: Enache Sebastian | B9: Conducere | C9: Conferinta MG | E9: 45686 | F9: 45686 | G9: 45686 | H9: 1 | I9: Bucuresti | J9: Avion | O9: 57.5 | Q9: 610 | R9: 100 | S9: =SUM(N9:R9) -> 767.5
A10: Mezei Ioan | B10: Conducere | C10: Conferinta MG | E10: 45686 | F10: 45686 | G10: 45686 | H10: 1 | I10: Bucuresti | J10: Avion | O10: 57.5 | Q10: 610 | R10: 100 | S10: =SUM(N10:R10) -> 767.5
A11: Patrasc Roger | B11: Vanzari Audi | C11: Training manageri | E11: 45685 | F11: 45685 | G11: 45685 | H11: 1 | N11: 3545 | S11: =SUM(N11:R11) -> 3545
A12: Ovidiu Ciobanca | B12: Vanzari VW | C12: Training manageri | E12: 45685 | F12: 45685 | G12: 45685 | H12: 1 | N12: 3545 | S12: =SUM(N12:R12) -> 3545
A13: Raluca Asztalos | B13: Vanzari Volvo | C13: Training manageri | E13: 45685 | F13: 45685 | G13: 45685 | H13: 1 | N13: 3545 | S13: =SUM(N13:R13) -> 3545
A14: Ovidiu Bucur | B14: Vanzari DWA | C14: Training manageri | E14: 45685 | F14: 45685 | G14: 45685 | H14: 1 | N14: 3545 | S14: =SUM(N14:R14) -> 3545
A15: Madalina Morutan | B15: Motion | C15: Training manageri | E15: 45685 | F15: 45685 | G15: 45685 | H15: 1 | N15: 3545 | S15: =SUM(N15:R15) -> 3545
A16: Roxana Biris | B16: Vanzari MG | C16: Training manageri | E16: 45685 | F16: 45685 | G16: 45685 | H16: 1 | N16: 3545 | S16: =SUM(N16:R16) -> 3545
A17: Tudor Adrian | B17: Conducere | C17: Training manageri | E17: 45685 | F17: 45685 | G17: 45685 | H17: 1 | N17: 3545 | S17: =SUM(N17:R17) -> 3545
A18: Crisan Alin | B18: Piese de schimb si accesorii Audi | C18: PDA 1M1 P.1 Coordonator Siguranta Produselor | D18: PDA 1M1 P.1 | E18: 21-23.01.2025 | F18: 45677 | G18: 45680 | H18: 3 | I18: Bucuresti | J18: Masina | N18: 1508 | O18: 172.5 | P18: 1176 | S18: =SUM(N18:R18) -> 2856.5
A19: Istvan Papp | B19: Conducere | C19: Training administratori | E19: 45695 | F19: 45695 | G19: 45695 | H19: 1 | N19: 1092 | S19: =SUM(N19:R19) -> 1092
A20: Mezei Ioan | B20: Conducere | C20: Conferinta | E20: 45701 | F20: 45701 | G20: 45701 | H20: 1 | I20: Bucuresti | J20: Avion | O20: 57.5 | P20: 367 | Q20: 546 | S20: =SUM(N20:R20) -> 970.5
A21: Mihaela Rosca | B21: Marketing | C21: Training manageri | E21: 45705 | F21: 45705 | G21: 45705 | H21: 1 | N21: 3017 | S21: =SUM(N21:R21) -> 3017
A22: Tudor Adrian | B22: Conducere | C22: Training manageri | E22: 45705 | F22: 45705 | G22: 45705 | H22: 1 | N22: 3017 | S22: =SUM(N22:R22) -> 3017
A23: Danci Gabriel | B23: Service MG | C23: MG Product Introduction & MG AS33 ICE | E23: 27-31.01.2025 | F23: 45683 | G23: 45688 | H23: 5 | I23: Bucuresti | J23: Masina | O23: 287.5 | P23: 1037 | S23: =SUM(N23:R23) -> 1324.5
B24: Conducere | C24: Training manageri | E24: 45743 | F24: 45743 | G24: 45743 | H24: 1 | N24: 7092 | S24: =SUM(N24:R24) -> 7092
A25: Mezei Laszlo Lehel | B25: Conducere | C25: Volkswagen Brand Experience | E25: 17-18.03.2025 | F25: 45733 | G25: 45734 | I25: Bucuresti | J25: Avion | O25: 261 | Q25: 616 | R25: 100 | S25: =SUM(N25:R25) -> 977
A26: Mezei Ioan | B26: Conducere | C26: Intalniri business | E26: 45742 | F26: 45742 | G26: 45742 | H26: 1 | I26: Bucuresti | J26: Avion | O26: 57.5 | Q26: 934 | S26: =SUM(N26:R26) -> 991.5
B27: Conducere | C27: Program coaching si workshop martie 2025 | E27: 45747 | F27: 45747 | G27: 45747 | H27: 3 | I27: Cluj-Napoca | N27: 100862 | S27: =SUM(N27:R27) -> 100862
A28: Enache Sebastian | B28: Conducere | C28: Intalnire Toyota | E28: 45697 | F28: 45697 | G28: 45697 | H28: 1 | I28: Bucuresti | J28: Avion | O28: 57.5 | R28: 100 | S28: =SUM(N28:R28) -> 157.5
A29: Istvan Papp | B29: Conducere | C29: Training administratori | E29: 45742 | F29: 45742 | G29: 45742 | H29: 1 | N29: 1539 | S29: =SUM(N29:R29) -> 1539
A30: Szabo Alexandru | B30: Conducere | C30: Eveniment AD AUTO TOTAL | E30: 17-18.05.2025 | F30: 45793 | G30: 45795 | H30: 2 | I30: Bucuresti | J30: Avion | O30: 115 | P30: 1293 | Q30: 708 | S30: =SUM(N30:R30) -> 2116
A31: Enache Sebastian | B31: Conducere | C31: PFG GRAND PRIX F1 SPANIA | E31: 30.05.2025-01.06.2025 | F31: 45806 | G31: 45810 | H31: 4 | I31: Barcelona | J31: Avion | O31: 588.5 | R31: 150 | S31: =SUM(N31:R31) -> 738.5
A32: Cretiu Monica | B32: Vanzari Audi | C32: Curs PFG | E32: 16-17.06.2025 | F32: 45824 | G32: 45825 | H32: 2 | I32: Bucuresti | J32: Avion | O32: 120 | S32: =SUM(N32:R32) -> 120
A33: Chindris Ramona | B33: Vanzari VW | C33: Curs PFG | E33: 16-17.06.2025 | F33: 45824 | G33: 45825 | H33: 2 | I33: Bucuresti | J33: Avion | O33: 120 | S33: =SUM(N33:R33) -> 120
A34: Mezei Ioan | B34: Conducere | C34: Conferinta | I34: Bucuresti | J34: Avion | O34: 57.5 | Q34: 1840 | S34: =SUM(N34:R34) -> 1897.5
A35: Istvan Papp | B35: Conducere | C35: Training administratori | E35: 45793 | F35: 45793 | G35: 45793 | H35: 1 | N35: 1154 | S35: =SUM(N35:R35) -> 1154
A36: Mezei Ioan | B36: Conducere | C36: Intalniri business | E36: 45845 | F36: 45845 | G36: 45845 | H36: 1 | J36: Avion | O36: 57.5 | S36: =SUM(N36:R36) -> 57.5
A37: Mezei Ioan | B37: Conducere | C37: Vizita clienti si prospectare piata | E37: 18-21.08.2025 | F37: 45887 | G37: 45890 | H37: 4 | J37: Avion | O37: 700 | S37: =SUM(N37:R37) -> 700
A38: Mezei Laszlo Lehel | B38: Conducere | C38: Vizita clienti si prospectare piata | E38: 18-21.08.2025 | F38: 45887 | G38: 45890 | H38: 4 | J38: Avion | O38: 700 | S38: =SUM(N38:R38) -> 700
A39: Mezei Ioan | B39: Conducere | C39: Vizite importatori | E39: 45908 | F39: 45908 | G39: 45908 | H39: 1 | I39: Bucuresti | J39: Avion | O39: 57.5 | Q39: 765 | S39: =SUM(N39:R39) -> 822.5
A40: Mezei Laszlo Lehel | B40: Conducere | C40: Vizite importatori | E40: 45908 | F40: 45908 | G40: 45908 | H40: 1 | I40: Bucuresti | J40: Avion | O40: 57.5 | Q40: 765 | S40: =SUM(N40:R40) -> 822.5
...

Sheet Cursuri AW International
A1: Nume & Prenume | B1: Departament | C1: Denumire Curs / Conferinta | D1: Cod curs | E1: Durata curs | F1: Data inceput curs | G1: Data final curs | H1: Nr zile curs | I1: Locatia | J1: Deplasare | K1: Nec. Nr. | L1: OD | M1: Act adit. | N1: Taxa training | O1: Diurna | P1: Cazare | Q1: Transport | R1: Taxi | S1: COST TOTAL
A2: Foszto Tamas Tibor | B2: Service VW | C2: API Skoda 2024-2 Informatii actuale despre produs | E2: 45692 | F2: 45692 | G2: 45692 | H2: 1 | I2: Bucuresti | J2: Avion | L2: 15 | N2: 503 | O2: 57.5 | Q2: 602 | R2: 100 | S2: =SUM(N2:R2) -> 1262.5
A3: Moise George | B3: Service VW | C3: PTA 8HT P.1 Tehnician Inalta Tensiune | D3: PTA 8HT P.1 | E3: 18-19.02.2025 | F3: 45705 | G3: 45707 | H3: 3 | I3: Bucuresti | J3: Masina | L3: 102 | N3: 1005 | O3: 172.5 | S3: =SUM(N3:R3) -> 1177.5
A4: Pop Marius | B4: Vanzari VW | C4: Brand Experience 2025 (Noul Transporter) | E4: 21-22.02.2025 | F4: 45708 | G4: 45711 | H4: 3 | I4: Atena | J4: Avion | L4: 103 | O4: 853 | P4: 749 | Q4: 2132 | R4: 200 | S4: =SUM(N4:R4) -> 3934
A5: Ciobanca Ovidiu | B5: Vanzari VW | C5: Training manager | E5: 45716 | F5: 45716 | G5: 45716 | H5: 1 | N5: 3152 | S5: =SUM(N5:R5) -> 3152
B6: Vanzari VW | C6: Scolarizare vanzatori (Nechita M, Ungurean I, Ungur F, Popa D, Zemba P, Aszalos C, Darvas Z, Dragos G, Burca F) | E6: 45716 | F6: 45716 | G6: 45716 | H6: 1 | N6: 14200 | S6: =SUM(N6:R6) -> 14200
A7: Ciobanca Ovidiu | B7: Vanzari VW | C7: Volkswagen Brand Experience | E7: 17-18.03.2025 | F7: 45733 | G7: 45734 | H7: 2 | I7: Dusseldorf | J7: Avion | L7: 338 | O7: 232.5 | Q7: 616 | R7: 100 | S7: =SUM(N7:R7) -> 948.5
A8: Capota Teodora | B8: Vanzari VW | C8: Volkswagen Brand Experience | E8: 17-18.03.2025 | F8: 45733 | G8: 45734 | H8: 2 | I8: Dusseldorf | J8: Avion | L8: 339 | O8: 232.5 | Q8: 616 | R8: 100 | S8: =SUM(N8:R8) -> 948.5
A9: Ioan Parocescu | B9: Service VW | C9: Volkswagen Brand Experience | E9: 17-18.03.2025 | F9: 45733 | G9: 45734 | H9: 2 | I9: Dusseldorf | J9: Avion | L9: 340 | O9: 232.5 | Q9: 616 | R9: 100 | S9: =SUM(N9:R9) -> 948.5
A10: Toma Cezar | B10: Service VW | C10: PNA 2M2 P.1 Modul 2 Consilier Service | D10: PNA 2M2 P.1 | E10: 25-28.03.2025 | F10: 45740 | G10: 45744 | H10: 4 | I10: Bucuresti | J10: Masina | L10: 411 | N10: 2011 | O10: 230 | P10: 1807 | S10: =SUM(N10:R10) -> 4048
A11: Kis Balasz | B11: Service VW | C11: ABE 1Q6 + A5 P.1 Caroserie Audi Q6 e-tron si A5 | D11: ABE 1Q6 + A5 P.1 | E11: 27-28.03.2025 | F11: 45742 | G11: 45744 | H11: 3 | I11: Bucuresti | J11: Masina | L11: 441 | N11: 1005 | O11: 172.5 | P11: 895 | S11: =SUM(N11:R11) -> 2072.5
A12: Ciobanca Ovidiu | B12: Vanzari VW | C12: ASV Training | E12: 45747 | F12: 45747 | G12: 45747 | H12: 1 | N12: 3546 | S12: =SUM(N12:R12) -> 3546
A13: Ciobanca Ovidiu | B13: Vanzari VW | C13: Intalniri business | E13: 45749 | F13: 45749 | G13: 45749 | H13: 1 | I13: Bucuresti | J13: Avion | L13: 488 | O13: 57.5 | P13: 616 | R13: 100 | S13: =SUM(N13:R13) -> 773.5
A14: Bercea Ancuta | B14: Service VW | C14: PDA 1M1 P.1 - Coordonator siguranta produselor | D14: PDA 1M1 P.1 | E14: 23-25.04.2025 | F14: 45770 | G14: 45772 | H14: 3 | I14: Bucuresti | J14: Avion | L14: 646 | N14: 1508 | O14: 172.5 | P14: 904 | Q14: 616 | R14: 150 | S14: =SUM(N14:R14) -> 3350.5
A15: Foszto Tamas Tibor | B15: Service VW | C15: CTE 251 P.1 Skoda Elroq si noutăți tehnice pentru tehnicieni | D15: CTE 251 P.1 | E15: 29-30.04.2025 | F15: 45776 | G15: 45777 | H15: 2 | I15: Bucuresti | J15: Avion | L15: 693 | N15: 1905 | O15: 115 | P15: 452 | Q15: 616 | R15: 300 | S15: =SUM(N15:R15) -> 3388
A16: Adrian Popescu | B16: Service VW | C16: Curs inspector SSM | E16: 45784 | F16: 45784 | G16: 45784 | H16: 1 | N16: 950 | S16: =SUM(N16:R16) -> 950
A17: Moise George | B17: Service VW | C17: NTE 251-1 P.1 VW Transporter 2025 pentru tehnicieni | D17: NTE 251-1 P.1 VW | E17: 06-08.05.2025 | F17: 45782 | G17: 45785 | H17: 4 | I17: Bucuresti | J17: Avion | L17: 629 | N17: 1550 | O17: 230 | S17: =SUM(N17:R17) -> 1780
A18: Toma Cezar | B18: Service VW | C18: NTE 251-2 P.1 VW Transporter 2025 pentru consilieri | D18: NTE 251-2 P.1 VW | E18: 29-30.05.2025 | F18: 45806 | G18: 45807 | H18: 2 | I18: Bucuresti | J18: Avion | L18: 893 | N18: 1550 | O18: 115 | P18: 459 | Q18: 616 | R18: 200 | S18: =SUM(N18:R18) -> 2940
A19: Sabou Alexandru | B19: Service VW | C19: Seminar Pregatirea suprafetelor Standox | E19: 13-15.05.2025 | F19: 45789 | G19: 45792 | H19: 4 | I19: Bucuresti | J19: Masina | L19: 783 | O19: 230 | P19: 193 | S19: =SUM(N19:R19) -> 423
A20: Bodogan Sandor | B20: Service VW | C20: Seminar Pregatirea suprafetelor Standox | E20: 13-15.05.2025 | F20: 45789 | G20: 45792 | H20: 4 | I20: Bucuresti | J20: Masina | L20: 782 | O20: 230 | P20: 193 | S20: =SUM(N20:R20) -> 423
A21: Aszalos Cristian | B21: Vanzari VW | C21: IBT Modul 1 Certificare | E21: 12-15.05.2025 | F21: 45789 | G21: 45792 | H21: 4 | I21: Brasov | J21: Masina | L21: 839 | N21: 2075 | O21: 230 | S21: =SUM(N21:R21) -> 2305
A22: Dragos popa | B22: Vanzari VW | C22: IBT Modul 1 Certificare | E22: 12-15.05.2025 | F22: 45789 | G22: 45792 | H22: 4 | I22: Brasov | J22: Masina | L22: 840 | N22: 2075 | O22: 230 | S22: =SUM(N22:R22) -> 2305
A23: Ciobanca Ovidiu | B23: Vanzari VW | C23: Training manager | E23: 45793 | F23: 45793 | G23: 45793 | H23: 1 | N23: 3546 | S23: =SUM(N23:R23) -> 3546
A24: Ciobanca Ovidiu | B24: Vanzari VW | C24: PFG GRAND PRIX F1 SPANIA | E24: 30.05.2025-01.06.2025 | F24: 45806 | G24: 45810 | H24: 5 | I24: Barcelona | J24: Avion | L24: 924 | O24: 643.84 | S24: =SUM(N24:R24) -> 643.84
A25: Ciobanca Ovidiu | B25: Vanzari VW | C25: Sales Meeting PKW | E25: 45811 | F25: 45811 | G25: 45811 | H25: 1 | I25: Bucuresti | J25: Avion | L25: 927 | O25: 57.5 | Q25: 732 | R25: 100 | S25: =SUM(N25:R25) -> 889.5
A26: Capota Teodora | B26: Vanzari VW | C26: Sales Meeting PKW | E26: 45811 | F26: 45811 | G26: 45811 | H26: 1 | I26: Bucuresti | J26: Avion | L26: 928 | O26: 57.5 | Q26: 732 | R26: 100 | S26: =SUM(N26:R26) -> 889.5
A27: Tadici Constantin | B27: Piese de schimb si accesorii VW | C27: Tur fabrica Continental Timisoara | E27: 05-06.06.2025 | F27: 45812 | G27: 45814 | H27: 2 | I27: Timisoara | J27: Masina | L27: 962 | O27: 115 | S27: =SUM(N27:R27) -> 115
A28: Ciobanca Ovidiu | B28: Vanzari VW | C28: Curs VW BEX | E28: 45813 | F28: 45813 | G28: 45813 | H28: 1 | N28: 8342 | S28: =SUM(N28:R28) -> 8342
A29: Parocescu Ioan | B29: Service VW | C29: Curs VW BEX | E29: 45813 | F29: 45813 | G29: 45813 | H29: 1 | N29: 2781 | S29: =SUM(N29:R29) -> 2781
A30: Toma Cezar | B30: Service VW | C30: PNA 2M4 P.1 Modul 4 Consilier Service | D30: PNA 2M4 P.1 | E30: 17-20.06.2025 | F30: 45824 | G30: 45828 | H30: 5 | I30: Bucuresti | J30: Masina | L30: 1034 | N30: 2500 | O30: 287.5 | P30: 1025 | S30: =SUM(N30:R30) -> 3812.5
A31: Sabou Alexandru | B31: Service VW | C31: Program scolarizari Standox 2025 | E31: 24-26.06.2025 | F31: 45831 | G31: 45834 | H31: 4 | I31: Bucuresti | J31: Masina | L31: 1137 | O31: 230 | P31: 675 | S31: =SUM(N31:R31) -> 905
A32: Bodogan Sandor | B32: Service VW | C32: Program scolarizari Standox 2025 | E32: 24-26.06.2025 | F32: 45831 | G32: 45834 | H32: 4 | I32: Bucuresti | J32: Masina | L32: 1138 | O32: 230 | P32: 675 | S32: =SUM(N32:R32) -> 905
A33: Popa Dragos | B33: Vanzari VW | C33: Basic Training Sales | E33: 45832 | F33: 45832 | G33: 45832 | H33: 1 | N33: 2075 | S33: =SUM(N33:R33) -> 2075
A34: Cristian Aszalos | B34: Vanzari VW | C34: Basic Training Sales | E34: 45832 | F34: 45832 | G34: 45832 | H34: 1 | N34: 2075 | S34: =SUM(N34:R34) -> 2075
A35: Moise George | B35: Service VW | C35: PTA MEX P.1 Examen certificare Tehnician Service | D35: PTA MEX P.1 | E35: 45849 | F35: 45848 | G35: 45849 | H35: 2 | I35: Bucuresti | J35: Masina | N35: 512 | O35: 115 | S35: =SUM(N35:R35) -> 627
A36: Persa Paul | B36: Service VW | C36: PTA MEX P.1 Examen certificare Tehnician Service | D36: PTA MEX P.1 | E36: 45849 | F36: 45848 | G36: 45849 | H36: 2 | I36: Bucuresti | J36: Masina | N36: 512 | O36: 115 | S36: =SUM(N36:R36) -> 627
A37: Toma Cezar | B37: Service VW | C37: PNA 2EX P.1. - Examen certificare consilier service | D37: PNA 2EX P.1. | E37: 45855 | F37: 45854 | G37: 45855 | H37: 2 | I37: Bucuresti | N37: 512 | O37: 115 | P37: 228 | S37: =SUM(N37:R37) -> 855
A38: Aszalos Cristian | B38: Vanzari VW | C38: IBT ( Basic Training Sales) - Modul 3 | E38: 11-14.08.2025 | F38: 45880 | G38: 45883 | H38: 4 | I38: Brasov | J38: Masina | O38: 230 | S38: =SUM(N38:R38) -> 230
A39: Popa Dragos | B39: Vanzari VW | C39: IBT ( Basic Training Sales) - Modul 3 | E39: 11-14.08.2025 | F39: 45880 | G39: 45883 | H39: 4 | I39: Brasov | J39: Masina | O39: 230 | S39: =SUM(N39:R39) -> 230
A40: Ciobanca Ovidiu | B40: Vanzari VW | C40: Intalnire importator PORO | E40: 45870 | F40: 45870 | G40: 45870 | H40: 1 | I40: Bucuresti | J40: Avion | O40: 57.5 | S40: =SUM(N40:R40) -> 57.5
...

Sheet Cursuri AW Premium
A1: Nume & Prenume | B1: Departament | C1: Denumire Curs / Conferinta | D1: Cod curs | E1: Durata curs | F1: Data plecare | G1: Data intoarcere | H1: Nr zile curs | I1: Locatia | J1: Deplasare | K1: Nec. Nr. | L1: OD | M1: Act adit. | N1: Taxa training | O1: Diurna | P1: Cazare | Q1: Transport | R1: Taxi | S1: COST TOTAL
A2: Jarda Andrei | B2: Service Audi | C2: ATE 0Q6 + ATE 0A5 P.1 Audi Q6 e-tron si A5 pentru tehnicieni | D2: ATE 0Q6 + ATE 0A5 P.1 | E2: 18-21.02.2025 | F2: 45706 | G2: 45709 | H2: 4 | I2: Bucuresti | J2: Avion | L2: 142 | N2: 2011 | O2: 230 | P2: 1079 | Q2: 581 | R2: 200 | S2: =SUM(N2:R2) -> 4101
A3: Dan Alexandru | B3: Service Audi | C3: ATE 1Q6 + ATE 1A5 P.1 Audi Q6 e-tron si A5 pentru consilieri | D3: ATE 1Q6 + ATE 1A5 P.1 | E3: 27-28.02.2025 | F3: 45715 | G3: 45716 | H3: 2 | I3: Bucuresti | J3: Avion | L3: 197 | N3: 1005 | O3: 115 | P3: 360 | Q3: 581 | S3: =SUM(N3:R3) -> 2061
A4: Patrasc Roger | B4: Vanzari Audi | C4: Training manageri | E4: 45716 | F4: 45716 | G4: 45716 | H4: 1 | N4: 3152 | S4: =SUM(N4:R4) -> 3152
A5: Dolean Florian | B5: Service Audi | C5: TE 0Q6 + ATE 0A5 P.1 Audi Q6 e-tron si A5 pentru tehnicieni | D5: TE 0Q6 + ATE 0A5 P.1 | E5: 04-07.03.2025 | F5: 45720 | G5: 45723 | H5: 4 | I5: Bucuresti | J5: Avion | L5: 285 | N5: 2010 | O5: 230 | P5: 1356 | Q5: 325 | S5: =SUM(N5:R5) -> 3921
A6: Oproae Grigore | B6: Service Audi | C6: ATE 0Q6 + ATE 0A5 P.1 Audi Q6 e-tron si A5 | D6: ATE 0Q6 + ATE 0A5 P.1 | E6: 18-21.03.2025 | F6: 45734 | G6: 45737 | H6: 4 | I6: Bucuresti | J6: Avion | L6: 412 | N6: 2011 | O6: 230 | P6: 1356 | Q6: 663 | S6: =SUM(N6:R6) -> 4260
A7: Patrasc Roger | B7: Vanzari Audi | C7: Training manageri ASV | E7: 45747 | F7: 45747 | G7: 45747 | H7: 1 | N7: 3546 | S7: =SUM(N7:R7) -> 3546
A8: Popa Alexandru | B8: Service Audi | C8: PDA 1M1 P.1 - Coordonator siguranta produselor | D8: PDA 1M1 P.1 | E8: 09-11.04.2025 | F8: 45756 | G8: 45758 | H8: 3 | I8: Bucuresti | J8: Avion | L8: 602 | N8: 1508 | O8: 172.5 | P8: 904 | R8: 200 | S8: =SUM(N8:R8) -> 2784.5
A9: Dan Alexandru | B9: Service Audi | C9: PNA 2M4 P.1 Modul 4 Consilier Service | D9: PNA 2M4 P.1 | E9: 17-20.06.2025 | F9: 45824 | G9: 45828 | H9: 5 | I9: Bucuresti | J9: Masina | L9: 1137 | N9: 2033 | O9: 287.5 | P9: 1025 | S9: =SUM(N9:R9) -> 3345.5
A10: Crisan Alin | B10: Piese de schimb si accesorii Audi | C10: Tur fabrica Continental Timisoara | E10: 05-06.06.2025 | F10: 45812 | G10: 45814 | H10: 2 | I10: Timisoara | J10: Masina | L10: 1069 | O10: 115 | S10: =SUM(N10:R10) -> 115
A11: Dolean Florian | B11: Service Audi | C11: Instruire | E11: 45783 | F11: 45783 | G11: 45783 | H11: 1 | N11: 900 | S11: =SUM(N11:R11) -> 900
A12: Duca Calin | B12: Service Audi | C12: Certificat atestare RAR | E12: 45841 | F12: 45841 | G12: 45841 | H12: 1 | N12: 189 | S12: =SUM(N12:R12) -> 189
A13: Dan Alexandru | B13: Service Audi | C13: PNA 2EX P.1. - Examen certificare consilier service | D13: PNA 2EX P.1 | E13: 45855 | F13: 45854 | G13: 45855 | H13: 2 | I13: Bucuresti | J13: Masina | N13: 512 | O13: 115 | P13: 228 | S13: =SUM(N13:R13) -> 855
A14: Jarda Andrei | B14: Service Audi | C14: Examen certificare tehnician service | E14: 45855 | F14: 45854 | G14: 45855 | H14: 2 | I14: Bucuresti | J14: Masina | N14: 512 | O14: 115 | S14: =SUM(N14:R14) -> 627
A15: Popescu Flavius | B15: Service Audi | C15: Examen certificare tehnician service | E15: 45855 | F15: 45854 | G15: 45855 | H15: 2 | I15: Bucuresti | J15: Masina | N15: 512 | O15: 115 | S15: =SUM(N15:R15) -> 627
A16: Patrasc Roger | B16: Vanzari Audi | C16: Intalniri PORO | E16: 45862 | F16: 45862 | G16: 45862 | H16: 1 | I16: Bucuresti | J16: Avion | O16: 57.5 | S16: =SUM(N16:R16) -> 57.5
A17: Oancea Mihai | B17: Vanzari Audi | C17: CLX 2025 Audi A6 Avant training digital | E17: 10-12.08.2025 | F17: 45879 | G17: 45881 | H17: 3 | I17: Munchen | J17: Avion | O17: 443 | S17: =SUM(N17:R17) -> 443
A18: Crisan Alin | B18: Piese de schimb si accesorii Audi | C18: CLX 2025 Audi A6 Avant training digital | E18: 10-12.08.2025 | F18: 45879 | G18: 45881 | H18: 3 | I18: Munchen | J18: Avion | O18: 443 | S18: =SUM(N18:R18) -> 443
A19: Bejan Medela | B19: Vanzari Audi | C19: CLX 2025 Audi A6 Avant training digital | E19: 10-12.08.2025 | F19: 45879 | G19: 45881 | H19: 3 | I19: Munchen | J19: Avion | O19: 443 | S19: =SUM(N19:R19) -> 443
A20: Dan Alexandru | B20: Service Audi | C20: CLX 2025 Audi A6 Avant training digital | E20: 10-12.08.2025 | F20: 45879 | G20: 45881 | H20: 3 | I20: Munchen | J20: Avion | O20: 443 | S20: =SUM(N20:R20) -> 443
A21: Vilcan Alexandru | B21: Vanzari Audi | C21: CLX 2025 Audi A6 Avant training digital | E21: 12-14.08.2025 | F21: 45881 | G21: 45883 | H21: 3 | I21: Munchen | J21: Avion | O21: 443 | S21: =SUM(N21:R21) -> 443
A22: Petrutiu Paula | B22: Vanzari Audi | C22: CLX 2025 Audi A6 Avant training digital | E22: 12-14.08.2025 | F22: 45881 | G22: 45883 | H22: 3 | I22: Munchen | J22: Avion | O22: 443 | S22: =SUM(N22:R22) -> 443
A23: Patrasc Roger | B23: Vanzari Audi | C23: CLX 2025 Audi A6 Avant training digital | E23: 12-14.08.2025 | F23: 45881 | G23: 45883 | H23: 3 | I23: Munchen | J23: Avion | O23: 443 | S23: =SUM(N23:R23) -> 443
A24: Duca Calin | B24: Service Audi | C24: CLX 2025 Audi A6 Avant training digital | E24: 12-14.08.2025 | F24: 45881 | G24: 45883 | H24: 3 | I24: Munchen | J24: Avion | O24: 443 | S24: =SUM(N24:R24) -> 443
A25: Patrasc Roger | B25: Vanzari Audi | C25: Audi Retail Experience for Leaders | E25: 45925 | F25: 45925 | G25: 45925 | H25: 1 | I25: Bucuresti | J25: Avion | O25: 57.5 | Q25: 510 | S25: =SUM(N25:R25) -> 567.5
A26: Patrasc Roger | B26: Vanzari Audi | C26: Training Audi Leadership in Action | E26: 03-07.11.2025 | F26: 03.11.2025 | G26: 07.11.2025 | H26: 5 | I26: Bucuresti | J26: Avion | O26: 287.5 | S26: =SUM(N26:R26) -> 287.5
A27: Duca Calin | B27: Service Audi | C27: Conferinta After Sales 2025 | E27: 13-14.11.2025 | F27: 45974 | G27: 45975 | H27: 2 | I27: Poiana Brasov | J27: Masina | O27: 115 | S27: =SUM(N27:R27) -> 115
S28: =SUM(N28:R28) -> 0
S29: =SUM(N29:R29) -> 0
S30: =SUM(N30:R30) -> 0
S31: =SUM(N31:R31) -> 0
S32: =SUM(N32:R32) -> 0
S33: =SUM(N33:R33) -> 0
S34: =SUM(N34:R34) -> 0
S35: =SUM(N35:R35) -> 0
S36: =SUM(N36:R36) -> 0
S37: =SUM(N37:R37) -> 0
S38: =SUM(N38:R38) -> 0
S39: =SUM(N39:R39) -> 0
... S525: =SUM(N525:R525) -> 0

Sheet Cursuri AW Prestige
A1: Nume & Prenume | B1: Departament | C1: Denumire Curs / Conferinta | D1: Cod curs | E1: Durata curs | F1: Data inceput curs | G1: Data final curs | H1: Nr zile curs | I1: Locatia | J1: Deplasare | K1: Nec. Nr. | L1: OD | M1: Act adit. | N1: Taxa training | O1: Diurna | P1: Cazare | Q1: Transport | R1: Taxi | S1: COST TOTAL
A2: Popa Augustin | B2: Service Volvo | C2: Atestat RAR | E2: 45695 | F2: 45695 | G2: 45695 | H2: 1 | N2: 184 | S2: =SUM(N2:R2) -> 184
A3: Morutan Madalina | B3: Vanzari Volvo | C3: Training Manageri | E3: 45716 | F3: 45716 | G3: 45716 | H3: 1 | N3: 3152 | S3: =SUM(N3:R3) -> 3152
A4: Ploscar Mihai | B4: Service Volvo | C4: Training Manageri ASV | E4: 45747 | F4: 45747 | G4: 45747 | H4: 1 | N4: 3546 | S4: =SUM(N4:R4) -> 3546
A5: Szabo Attila | B5: Service Volvo | C5: Instruire | E5: 45784 | F5: 45784 | G5: 45784 | H5: 1 | N5: 900 | S5: =SUM(N5:R5) -> 900
A6: Berekmeri Arpad | B6: Service Volvo | C6: Seminar Pregatirea suprafetelor Standox | E6: 13-15.05.2025 | F6: 45790 | G6: 45792 | H6: 4 | I6: Bucuresti | J6: Masina | L6: 620 | O6: 230 | P6: 578 | S6: =SUM(N6:R6) -> 808
A7: Safta Stelian | B7: Service Volvo | C7: Seminar Pregatirea suprafetelor Standox | E7: 13-15.05.2025 | F7: 45790 | G7: 45792 | H7: 4 | I7: Bucuresti | J7: Masina | L7: 619 | O7: 230 | P7: 578 | S7: =SUM(N7:R7) -> 808
A8: Morutan Madalina | B8: Vanzari Volvo | C8: Volvo Training Sales & Marketing 2025 | E8: 05-06.06.2025 | F8: 45812 | G8: 45814 | H8: 2 | I8: Bucuresti | J8: Masina | L8: 711 | O8: 115 | P8: 918 | S8: =SUM(N8:R8) -> 1033
A9: Balanean Raluca | B9: Vanzari Volvo | C9: Volvo Training Sales & Marketing 2025 | E9: 05-06.06.2025 | F9: 45812 | G9: 45814 | H9: 2 | I9: Bucuresti | J9: Masina | L9: 712 | O9: 115 | P9: 459 | S9: =SUM(N9:R9) -> 574
A10: Stoica Cosmin | B10: Vanzari Volvo | C10: Volvo Training Sales & Marketing 2025 | E10: 05-06.06.2025 | F10: 45812 | G10: 45814 | H10: 2 | I10: Bucuresti | J10: Masina | L10: 713 | O10: 115 | P10: 1031 | S10: =SUM(N10:R10) -> 1146
A11: Erghelegiu Ioana | B11: Vanzari Volvo | C11: Volvo Training Sales & Marketing 2025 | E11: 05-06.06.2025 | F11: 45812 | G11: 45812 | H11: 2 | I11: Bucuresti | J11: Masina | L11: 714 | O11: 115 | P11: 459 | S11: =SUM(N11:R11) -> 574
A12: Berekmeri Arpad | B12: Service Volvo | C12: Program scolarizari Standox 2025 | E12: 24-26.06.2025 | F12: 45831 | G12: 45834 | H12: 4 | I12: Bucuresti | J12: Masina | L12: 813 | O12: 230 | P12: 620 | S12: =SUM(N12:R12) -> 850
A13: Safta Stelian | B13: Service Volvo | C13: Program scolarizari Standox 2025 | E13: 24-26.06.2025 | F13: 45831 | G13: 45834 | H13: 4 | I13: Bucuresti | J13: Masina | L13: 814 | O13: 230 | P13: 620 | S13: =SUM(N13:R13) -> 850
A14: Ploscar Mihai | B14: Service Volvo | C14: Intalnire Volvo | E14: 31.07.2025-01.08.2025 | F14: 45869 | G14: 45870 | H14: 2 | O14: 115 | S14: =SUM(N14:R14) -> 115
A15: Morutan Madalina | B15: Vanzari Volvo | C15: Intalniri importator | E15: 45887 | F15: 45887 | G15: 45887 | H15: 1 | I15: Bucuresti | J15: Avion | O15: 57.5 | S15: =SUM(N15:R15) -> 57.5
A16: Sarpatki Emoke | B16: Service Volvo | C16: Volvo Basic Program G1 | E16: 07-10.10.2025 | F16: 45937 | G16: 45940 | H16: 4 | O16: 230 | P16: 1015 | S16: =SUM(N16:R16) -> 1245
A17: Tolan Tudor | B17: Service Volvo | C17: Volvo Basic Program G1 | E17: 07-10.10.2025 | F17: 45937 | G17: 45940 | H17: 4 | O17: 230 | P17: 1015 | S17: =SUM(N17:R17) -> 1245
A18: Fodor Sorin | B18: Service Volvo | C18: Volvo Basic Program G1 | E18: 07-10.10.2025 | F18: 45937 | G18: 45940 | H18: 4 | O18: 230 | P18: 1015 | S18: =SUM(N18:R18) -> 1245
A19: Szabo Attila | B19: Service Volvo | C19: Final Phase EVT Training | E19: 23-25.10.2025 | F19: 45953 | G19: 45955 | H19: 3 | I19: Bucuresti | O19: 172.5 | S19: =SUM(N19:R19) -> 172.5
A20: Ples Mihai | B20: Service Volvo | C20: Final Phase EVT Training | E20: 23-25.10.2025 | F20: 45953 | G20: 45955 | H20: 3 | I20: Bucuresti | O20: 172.5 | S20: =SUM(N20:R20) -> 172.5
A21: Ples Mihai | B21: Service Volvo | C21: Final Phase AEVT Training | E21: 30.10.2025-01.11.2025 | F21: 45960 | G21: 45962 | H21: 3 | I21: Bucuresti | O21: 172.5 | S21: =SUM(N21:R21) -> 172.5
A22: Szabo Attila | B22: Service Volvo | C22: Final Phase AEVT Training | E22: 30.10.2025-01.11.2025 | F22: 45960 | G22: 45962 | H22: 3 | I22: Bucuresti | O22: 172.5 | S22: =SUM(N22:R22) -> 172.5
A23: Kallo Stefan | B23: Service Volvo | C23: Final Phase AEVT Training | E23: 30.10.2025-01.11.2025 | F23: 45960 | G23: 45962 | H23: 3 | I23: Bucuresti | O23: 172.5 | S23: =SUM(N23:R23) -> 172.5
S24: =SUM(N24:R24) -> 0
S25: =SUM(N25:R25) -> 0
S26: =SUM(N26:R26) -> 0
S27: =SUM(N27:R27) -> 0
S28: =SUM(N28:R28) -> 0
S29: =SUM(N29:R29) -> 0
S30: =SUM(N30:R30) -> 0
S31: =SUM(N31:R31) -> 0
S32: =SUM(N32:R32) -> 0
S33: =SUM(N33:R33) -> 0
S34: =SUM(N34:R34) -> 0
S35: =SUM(N35:R35) -> 0
... S527: =SUM(N527:R527) -> 0

Sheet Cursuri AW Plus
A1: Nume & Prenume | B1: Departament | C1: Denumire Curs / Conferinta | D1: Cod curs | E1: Durata curs | F1: Data inceput curs | G1: Data final curs | H1: Nr zile curs | I1: Locatia | J1: Deplasare | K1: Nec. Nr. | L1: OD | M1: Act adit. | N1: Taxa training | O1: Diurna | P1: Cazare | Q1: Transport | R1: Taxi | S1: COST TOTAL
A2: Mihai Damian | B2: Service MG | C2: Atestare cond loc de munca studii sup | E2: 45694 | F2: 45694 | G2: 45694 | H2: 1 | N2: 184 | S2: =SUM(N2:R2) -> 184
A3: Biris Roxana | B3: Vanzari MG | C3: Training manageri | E3: 45716 | F3: 45716 | G3: 45716 | N3: 3152 | S3: =SUM(N3:R3) -> 3152
A4: Danci Gabriel | B4: Service MG | C4: Curs tehnic Level 1 - MG Product Introduction & MG AS33 ICE | E4: 13-14.03.2025 | F4: 45728 | G4: 45730 | H4: 3 | I4: Bucuresti | J4: Masina | L4: 177 | N4: 1300 | O4: 172.5 | P4: 904 | S4: =SUM(N4:R4) -> 2376.5
A5: Harfas Roberto | B5: Vanzari MG | C5: Curs MG | E5: 19-20.03.2025 | F5: 45735 | G5: 45736 | H5: 2 | I5: Bucuresti | J5: Avion | L5: 198 | N5: 567 | O5: 115 | P5: 480 | Q5: 573 | R5: 100 | S5: =SUM(N5:R5) -> 1835
A6: Cuc Vlad | B6: Vanzari MG | C6: Curs MG | E6: 19-20.03.2025 | F6: 45735 | G6: 45736 | H6: 2 | I6: Bucuresti | J6: Avion | L6: 197 | N6: 567 | O6: 115 | P6: 480 | Q6: 573 | R6: 100 | S6: =SUM(N6:R6) -> 1835
A7: Graur Constantin | B7: Vanzari MG | C7: Curs MG | E7: 19-20.03.2025 | F7: 45735 | G7: 45736 | H7: 2 | I7: Bucuresti | J7: Avion | L7: 199 | N7: 567 | O7: 115 | P7: 480 | Q7: 573 | R7: 100 | S7: =SUM(N7:R7) -> 1835
A8: Biris Roxana | B8: Vanzari MG | C8: Training manageri ASV | E8: 45747 | F8: 45747 | G8: 45747 | H8: 1 | N8: 3546 | S8: =SUM(N8:R8) -> 3546
A9: Crisan Paul | B9: Piese de schimb si accesorii MG | C9: Curs comanda piese e-parts 2 | E9: 45771 | F9: 45771 | G9: 45771 | H9: 1 | I9: Bucuresti | J9: Avion | L9: 356 | O9: 57.5 | P9: 587 | Q9: 713 | R9: 100 | S9: =SUM(N9:R9) -> 1457.5
A10: Dan Vasile | B10: Service Mazda | C10: Curs instruire | E10: 45783 | F10: 45783 | G10: 45783 | H10: 1 | N10: 900 | S10: =SUM(N10:R10) -> 900
A11: Mihai Damian | B11: Service Mazda | C11: Curs SSM | E11: 45790 | F11: 45790 | G11: 45790 | H11: 1 | N11: 950 | S11: =SUM(N11:R11) -> 950
A12: Biris Roxana | B12: Vanzari MG | C12: Training manageri ASV | E12: 45792 | F12: 45792 | G12: 45792 | H12: 1 | N12: 3546 | S12: =SUM(N12:R12) -> 3546
A13: Danci Gabriel | B13: Service Mazda | C13: Curs High Voltage | E13: 45797 | F13: 45797 | G13: 45797 | H13: 1 | N13: 252 | S13: =SUM(N13:R13) -> 252
A14: Graur Constantin | B14: Vanzari MG | C14: Curs vanzari MG | E14: 04-05.06.2025 | F14: 45812 | G14: 45813 | H14: 2 | I14: Bucuresti | J14: Avion | O14: 115 | P14: 553 | Q14: 654 | S14: =SUM(N14:R14) -> 1322
A15: Danci Gabriel | B15: Service MG | C15: STT - ”Level 2 - Principiile Diagnosticarii si Aplicarea lor CEE-RO” si ”Mentenanta si Service CEE-RO” | E15: 17-19.06.2025 | F15: 45824 | G15: 45827 | H15: 4 | I15: Bucuresti | J15: Masina | L15: 652 | N15: 1950 | O15: 230 | P15: 836 | S15: =SUM(N15:R15) -> 3016
A16: Graur Constantin | B16: Vanzari MG | C16: Curs vanzari Modul 3/Contactarea si achizitia de clienti noi | E16: 24-25.09.2025 | F16: 45924 | G16: 45925 | H16: 1 | O16: 57.5 | P16: 577 | S16: =SUM(N16:R16) -> 634.5
A17: Morutan Madalina | B17: Vanzari Mazda | C17: Training produs Mazda | E17: 02-03.10.2025 | F17: 45932 | G17: 45934 | H17: 2 | O17: 350 | S17: =SUM(N17:R17) -> 350
A18: Dan Vasile | B18: Service Mazda | C18: Training produs Mazda | E18: 02-03.10.2025 | F18: 45932 | G18: 45934 | H18: 2 | O18: 350 | S18: =SUM(N18:R18) -> 350
A19: Istrate Adrian | B19: Vanzari Mazda | C19: Training produs Mazda | E19: 02-03.10.2025 | F19: 45932 | G19: 45934 | H19: 2 | O19: 350 | S19: =SUM(N19:R19) -> 350
A20: Vasiliu Alexandru | B20: Service Mazda | C20: Curs Mazda | E20: 45953 | F20: 45953 | G20: 45953 | H20: 1 | O20: 57.5 | Q20: 661 | S20: =SUM(N20:R20) -> 718.5
A21: Morutan Madalina | B21: Vanzari Mazda | C21: Training produs Mazda CX5 | E21: 45973 | F21: 45973 | G21: 45973 | H21: 1 | O21: 57.5 | S21: =SUM(N21:R21) -> 57.5
A22: Dan Vasile | B22: Service MG | C22: Training produs Mazda CX5 | E22: 45973 | F22: 45973 | G22: 45973 | H22: 1 | O22: 57.5 | S22: =SUM(N22:R22) -> 57.5
A23: Padurean Naomi | B23: Vanzari Mazda | C23: Training produs Mazda CX5 | E23: 45973 | F23: 45973 | G23: 45973 | H23: 1 | O23: 57.5 | S23: =SUM(N23:R23) -> 57.5
A24: Doja Paul | B24: Vanzari Mazda | C24: Training produs Mazda CX5 | E24: 45973 | F24: 45973 | G24: 45973 | H24: 1 | O24: 57.5 | S24: =SUM(N24:R24) -> 57.5
A25: Biris Roxana | B25: Vanzari MG | C25: Intalniri leasing operational | E25: 45979 | F25: 45979 | G25: 45979 | H25: 1 | O25: 57.5 | S25: =SUM(N25:R25) -> 57.5
A26: Dan Vasile | B26: Service Mazda | C26: Curs tehnic Mazda 6E | E26: 09-11.12.2025 | F26: 45999 | G26: 46003 | H26: 4 | O26: 716 | S26: =SUM(N26:R26) -> 716
S27: =SUM(N27:R27) -> 0
S28: =SUM(N28:R28) -> 0
S29: =SUM(N29:R29) -> 0
S30: =SUM(N30:R30) -> 0
S31: =SUM(N31:R31) -> 0
S32: =SUM(N32:R32) -> 0
S33: =SUM(N33:R33) -> 0
S34: =SUM(N34:R34) -> 0
S35: =SUM(N35:R35) -> 0
S36: =SUM(N36:R36) -> 0
S37: =SUM(N37:R37) -> 0
S38: =SUM(N38:R38) -> 0
... S530: =SUM(N530:R530) -> 0

Sheet Cursuri AW Next
A1: Nume & Prenume | B1: Departament | C1: Denumire Curs / Conferinta | D1: Cod curs | E1: Durata curs | F1: Data inceput curs | G1: Data final curs | H1: Nr zile curs | I1: Locatia | J1: Deplasare | K1: Nec. Nr. | L1: OD | M1: Act adit. | N1: Taxa training | O1: Diurna | P1: Cazare | Q1: Transport | R1: Taxi | S1: COST TOTAL
A2: Bucur Ovidiu | B2: Vanzari DWA | C2: Training manageri | E2: 45716 | F2: 45716 | G2: 45716 | H2: 1 | N2: 3152 | S2: =SUM(N2:R2) -> 3152
A3: Raluca Asztalos | B3: Vanzari Volvo | C3: Training manageri | E3: 45716 | F3: 45716 | G3: 45716 | H3: 1 | N3: 3152 | S3: =SUM(N3:R3) -> 3152
A4: Bucur Ovidiu | B4: Vanzari DWA | C4: Intalniri business | E4: 45749 | F4: 45749 | G4: 45749 | H4: 1 | I4: Bucuresti | J4: Avion | L4: 463 | O4: 57.5 | Q4: 616 | R4: 100 | S4: =SUM(N4:R4) -> 773.5
A5: Bucur Ovidiu | B5: Vanzari DWA | C5: Training manageri | E5: 45747 | F5: 45747 | G5: 45747 | H5: 1 | N5: 3546 | S5: =SUM(N5:R5) -> 3546
A6: Raluca Asztalos | B6: Vanzari Volvo | C6: Training manageri | E6: 45747 | F6: 45747 | G6: 45747 | H6: 1 | N6: 3546 | S6: =SUM(N6:R6) -> 3546
A7: Bucur Ovidiu | B7: Vanzari DWA | C7: Conferinta DasWeltAuto | E7: 07-08.10.2025 | F7: 45937 | G7: 45938 | H7: 2 | O7: 115 | S7: =SUM(N7:R7) -> 115
S8: =SUM(N8:R8) -> 0
S9: =SUM(N9:R9) -> 0
S10: =SUM(N10:R10) -> 0
S11: =SUM(N11:R11) -> 0
S12: =SUM(N12:R12) -> 0
S13: =SUM(N13:R13) -> 0
S14: =SUM(N14:R14) -> 0
S15: =SUM(N15:R15) -> 0
S16: =SUM(N16:R16) -> 0
S17: =SUM(N17:R17) -> 0
S18: =SUM(N18:R18) -> 0
S19: =SUM(N19:R19) -> 0
... S525: =SUM(N525:R525) -> 0

Sheet Cursuri AW One
A1: Nume & Prenume | B1: Departament | C1: Denumire Curs / Conferinta | D1: Cod curs | E1: Durata curs | F1: Data inceput curs | G1: Data final curs | H1: Nr zile curs | I1: Locatia | J1: Deplasare | K1: Nec. Nr. | L1: OD | M1: Act adit. | N1: Taxa training | O1: Diurna | P1: Cazare | Q1: Transport | R1: Taxi | S1: COST TOTAL
A2: Niculae Monica | B2: Vanzari Toyota | C2: Intalnire Toyota | E2: 45701 | F2: 45701 | G2: 45701 | H2: 1 | I2: Bucuresti | J2: Avion | O2: 57.5 | R2: 100 | S2: =SUM(N2:R2) -> 157.5
A3: Sfechis Sorin | B3: Vanzari Toyota | C3: Program training LCV Toyota Professional | E3: 01-02.04.2025 | F3: 45748 | G3: 45749 | H3: 2 | I3: Poiana Brasov | J3: Avion | O3: 115 | P3: 550 | S3: =SUM(N3:R3) -> 665
A4: Igli Denis | B4: Vanzari Toyota | C4: Curs "Academia de vanzari" Toyota | E4: 19-21.05.2025 | F4: 45796 | G4: 45798 | H4: 3 | I4: Sinaia | J4: Masina | O4: 172.5 | S4: =SUM(N4:R4) -> 172.5
A5: Sfechis Sorin | B5: Vanzari Toyota | C5: Curs "Academia de vanzari" Toyota | E5: 19-21.05.2025 | F5: 45796 | G5: 45798 | H5: 3 | I5: Sinaia | J5: Masina | O5: 172.5 | S5: =SUM(N5:R5) -> 172.5
A6: Marginean Raul | B6: Service Toyota | C6: Curs "Academia de vanzari" Toyota | E6: 19-21.05.2025 | F6: 45796 | G6: 45798 | H6: 3 | I6: Sinaia | J6: Masina | O6: 172.5 | S6: =SUM(N6:R6) -> 172.5
A7: Balatici Valentin | B7: Service Toyota | C7: Curs "Academia de vanzari" Toyota | E7: 19-21.05.2025 | F7: 45796 | G7: 45798 | H7: 3 | I7: Sinaia | J7: Masina | O7: 172.5 | S7: =SUM(N7:R7) -> 172.5
A8: Rusu Iulia | B8: Vanzari Toyota | C8: Curs "Academia de vanzari" Toyota | E8: 19-21.05.2025 | F8: 45796 | G8: 45798 | H8: 3 | I8: Sinaia | J8: Masina | O8: 172.5 | S8: =SUM(N8:R8) -> 172.5
A9: Sfechis Sorin | B9: Vanzari Toyota | C9: Program Training EV Sesiunea 5 iunie / Task proiect bZ4X luna iunie | E9: 45813 | F9: 45812 | G9: 45809 | H9: 2 | S9: =SUM(N9:R9) -> 0
A10: Rusu Iulia | B10: Vanzari Toyota | C10: Proces de Vanzare Sales si AFS, Certificare TME – Modulul 2 | E10: 10-12.11.2025 | F10: 10.11.2025 | G10: 12.11.2025 | H10: 2 | I10: Poiana Brasov | J10: masina | O10: 115 | S10: =SUM(N10:R10) -> 115
A11: Sfechis Sorin | B11: Vanzari Toyota | C11: Proces de Vanzare Sales si AFS, Certificare TME – Modulul 2 | E11: 10-12.11.2025 | F11: 10.11.2025 | G11: 12.11.2025 | H11: 2 | I11: Poiana Brasov | J11: masina | O11: 115 | S11: =SUM(N11:R11) -> 115
A12: Rusu Iulia | B12: Vanzari Toyota | C12: Intalniri leasing operational | E12: 18.11.2025 | F12: 18.11.2025 | G12: 18.11.2025 | H12: 1 | I12: Bucuresti | J12: avion | O12: 57.5 | R12: 100 | S12: =SUM(N12:R12) -> 157.5
A13: Monica Niculae | B13: Vanzari Toyota | C13: Intalniri leasing operational | E13: 18.11.2025 | F13: 18.11.2025 | G13: 18.11.2025 | H13: 1 | I13: Bucuresti | J13: avion | O13: 57.5 | R13: 100 | S13: =SUM(N13:R13) -> 157.5
A14: Monica Niculae | B14: Vanzari Toyota | C14: Intalnire business Toyota | E14: 27-28.11.2025 | F14: 27.11.2025 | G14: 27.11.2025 | H14: 1 | I14: Bucuresti | O14: 57.5 | P14: 650 | S14: =SUM(N14:R14) -> 707.5
A15: Oprea Ovidiu | B15: Service Toyota | C15: Intalnire business Toyota | E15: 27-28.11.2025 | F15: 27.11.2025 | G15: 27.11.2025 | H15: 1 | I15: Bucuresti | O15: 57.5 | P15: 650 | S15: =SUM(N15:R15) -> 707.5
S16: =SUM(N16:R16) -> 0
S17: =SUM(N17:R17) -> 0
S18: =SUM(N18:R18) -> 0
S19: =SUM(N19:R19) -> 0
S20: =SUM(N20:R20) -> 0
S21: =SUM(N21:R21) -> 0
S22: =SUM(N22:R22) -> 0
S23: =SUM(N23:R23) -> 0
S24: =SUM(N24:R24) -> 0
S25: =SUM(N25:R25) -> 0
S26: =SUM(N26:R26) -> 0
S27: =SUM(N27:R27) -> 0
... S523: =SUM(N523:R523) -> 0

Sheet Cursuri AW Insurance
A1: Nume & Prenume | B1: Departament | C1: Denumire Curs / Conferinta | D1: Cod curs | E1: Durata curs | F1: Data inceput curs | G1: Data final curs | H1: Nr zile curs | I1: Locatia | J1: Deplasare | K1: Nec. Nr. | L1: OD | M1: Act adit. | N1: Taxa training | O1: Diurna | P1: Cazare | Q1: Transport | R1: Taxi | S1: COST TOTAL
A2: Talos Camelia | B2: Asigurari | C2: Intalniri asiguratori | E2: 45756 | F2: 45756 | G2: 45756 | H2: 1 | I2: Bucuresti | J2: Avion | O2: 57.5 | S2: =SUM(N2:R2) -> 57.5
A3: Szabo Ioana | B3: Asigurari | C3: Intalniri asiguratori | E3: 45756 | F3: 45756 | G3: 45756 | H3: 1 | I3: Bucuresti | J3: Avion | O3: 57.5 | S3: =SUM(N3:R3) -> 57.5
S4: =SUM(N4:R4) -> 0
S5: =SUM(N5:R5) -> 0
S6: =SUM(N6:R6) -> 0
S7: =SUM(N7:R7) -> 0
S8: =SUM(N8:R8) -> 0
S9: =SUM(N9:R9) -> 0
S10: =SUM(N10:R10) -> 0
S11: =SUM(N11:R11) -> 0
S12: =SUM(N12:R12) -> 0
S13: =SUM(N13:R13) -> 0
S14: =SUM(N14:R14) -> 0
S15: =SUM(N15:R15) -> 0
... S523: =SUM(N523:R523) -> 0
